<?xml version="1.0" ?>
<!-- =================================================================================== -->
<!-- |    This document was autogenerated by xacro from robot.urdf.xacro               | -->
<!-- |    EDITING THIS FILE BY HAND IS NOT RECOMMENDED                                 | -->
<!-- =================================================================================== -->
<robot name="myfirst" xmlns:xacro="http://ros.org/wiki/xacro">
  <material name="color1">
    <color rgba="0 0.4 0.8 1"/>
  </material>
  <material name="color2">
    <color rgba="0 0.8 0.8 1"/>
  </material>
  <material name="color3">
    <color rgba="0 1 1 1"/>
  </material>
  <material name="color4">
    <color rgba="0 1 0.8 1"/>
  </material>
  <link name="base_link">
    <visual>
      <geometry>
        <box size="0.2 0.4 0.6"/>
      </geometry>
      <material name="color1"/>
    </visual>
    <collision>
      <geometry>
        <box size="0.2 0.4 0.6"/>
      </geometry>
    </collision>
    <inertial>
      <mass value="43.46"/>
      <inertia ixx="1.0" ixy="0.0" ixz="0.0" iyy="1.0" iyz="0.0" izz="1.0"/>
    </inertial>
  </link>
  <link name="head">
    <visual>
      <geometry>
        <box size="0.2 0.2 0.2"/>
      </geometry>
      <material name="color2"/>
    </visual>
    <collision>
      <geometry>
        <box size="0.2 0.2 0.2"/>
      </geometry>
    </collision>
    <inertial>
      <mass value="8.26"/>
      <inertia ixx="1.0" ixy="0.0" ixz="0.0" iyy="1.0" iyz="0.0" izz="1.0"/>
    </inertial>
  </link>
  <joint name="body_to_head" type="revolute">
    <parent link="base_link"/>
    <child link="head"/>
    <axis xyz="0 0 1"/>
    <limit effort="1000.0" lower="-0.5" upper="0.5" velocity="0.5"/>
    <origin xyz="0 0 0.4"/>
  </joint>
  <transmission name="body_to_head_trans">
    <type>transmission_interface/SimpleTransmission</type>
    <actuator name="body_to_head_motor">
      <mechanicalReduction>1</mechanicalReduction>
    </actuator>
    <joint name="body_to_head">
      <hardwareInterface>hardware_interface/VelocityJointInterface</hardwareInterface>
    </joint>
  </transmission>
  <link name="right_shoulder">
    <visual>
      <geometry>
        <box size="0.01 0.01 0.01"/>
      </geometry>
      <origin xyz="0 0.0 0.0"/>
      <material name="color2"/>
    </visual>
    <collision>
      <geometry>
        <box size="0.01 0.01 0.01"/>
      </geometry>
    </collision>
    <inertial>
      <mass value="0.01"/>
      <inertia ixx="1.0" ixy="0.0" ixz="0.0" iyy="1.0" iyz="0.0" izz="1.0"/>
    </inertial>
  </link>
  <joint name="body_to_right_shoulder" type="revolute">
    <parent link="base_link"/>
    <child link="right_shoulder"/>
    <axis xyz="1 0 0"/>
    <limit effort="1000.0" lower="-2.7" upper="-0.0" velocity="0.5"/>
    <origin xyz="0 -0.2 0.3"/>
  </joint>
  <transmission name="body_to_right_shoulder_trans">
    <type>transmission_interface/SimpleTransmission</type>
    <actuator name="body_to_right_shoulder_motor">
      <mechanicalReduction>1</mechanicalReduction>
    </actuator>
    <joint name="body_to_right_shoulder">
      <hardwareInterface>hardware_interface/VelocityJointInterface</hardwareInterface>
    </joint>
  </transmission>
  <link name="left_shoulder">
    <visual>
      <geometry>
        <box size="0.01 0.01 0.01"/>
      </geometry>
      <origin xyz="0 0.0 0.0"/>
      <material name="color2"/>
    </visual>
    <collision>
      <geometry>
        <box size="0.01 0.01 0.01"/>
      </geometry>
    </collision>
    <inertial>
      <mass value="0.01"/>
      <inertia ixx="1.0" ixy="0.0" ixz="0.0" iyy="1.0" iyz="0.0" izz="1.0"/>
    </inertial>
  </link>
  <joint name="body_to_left_shoulder" type="revolute">
    <parent link="base_link"/>
    <child link="left_shoulder"/>
    <axis xyz="1 0 0"/>
    <limit effort="1000.0" lower="-0.0" upper="2.7" velocity="0.5"/>
    <origin xyz="0 0.2 0.3"/>
  </joint>
  <transmission name="body_to_left_shoulder_trans">
    <type>transmission_interface/SimpleTransmission</type>
    <actuator name="body_to_left_shoulder_motor">
      <mechanicalReduction>1</mechanicalReduction>
    </actuator>
    <joint name="body_to_left_shoulder">
      <hardwareInterface>hardware_interface/VelocityJointInterface</hardwareInterface>
    </joint>
  </transmission>
  <link name="right_up_arm">
    <visual>
      <geometry>
        <box size="0.1 0.1 0.3"/>
      </geometry>
      <origin xyz="0 -0.05 -0.15"/>
      <material name="color2"/>
    </visual>
    <collision>
      <geometry>
        <box size="0.1 0.1 0.3"/>
      </geometry>
    </collision>
    <inertial>
      <mass value="2.71"/>
      <inertia ixx="1.0" ixy="0.0" ixz="0.0" iyy="1.0" iyz="0.0" izz="1.0"/>
    </inertial>
  </link>
  <link name="right_down_arm">
    <visual>
      <geometry>
        <box size="0.1 0.1 0.3"/>
      </geometry>
      <origin xyz="0 0 -0.15"/>
      <material name="color3"/>
    </visual>
    <collision>
      <geometry>
        <box size="0.1 0.1 0.3"/>
      </geometry>
    </collision>
    <inertial>
      <mass value="2.23"/>
      <inertia ixx="1.0" ixy="0.0" ixz="0.0" iyy="1.0" iyz="0.0" izz="1.0"/>
    </inertial>
  </link>
  <joint name="right_shoulder_to_right_up_arm" type="revolute">
    <parent link="right_shoulder"/>
    <child link="right_up_arm"/>
    <axis xyz="0 1 0"/>
    <limit effort="1000.0" lower="-2.7" upper="0.7" velocity="0.5"/>
    <origin xyz="0 0.0 0"/>
  </joint>
  <transmission name="right_shoulder_to_right_up_arm_trans">
    <type>transmission_interface/SimpleTransmission</type>
    <actuator name="right_shoulder_to_right_up_arm_motor">
      <mechanicalReduction>1</mechanicalReduction>
    </actuator>
    <joint name="right_shoulder_to_right_up_arm">
      <hardwareInterface>hardware_interface/VelocityJointInterface</hardwareInterface>
    </joint>
  </transmission>
  <joint name="right_up_arm_to_right_down_arm" type="revolute">
    <parent link="right_up_arm"/>
    <child link="right_down_arm"/>
    <axis xyz="0 1 0"/>
    <limit effort="1000.0" lower="-2.7" upper="0.5" velocity="0.5"/>
    <origin xyz="0 -0.05 -0.3"/>
  </joint>
  <transmission name="right_up_arm_to_right_down_arm_trans">
    <type>transmission_interface/SimpleTransmission</type>
    <actuator name="right_up_arm_to_right_down_arm_motor">
      <mechanicalReduction>1</mechanicalReduction>
    </actuator>
    <joint name="right_up_arm_to_right_down_arm">
      <hardwareInterface>hardware_interface/VelocityJointInterface</hardwareInterface>
    </joint>
  </transmission>
  <link name="left_up_arm">
    <visual>
      <geometry>
        <box size="0.1 0.1 0.3"/>
      </geometry>
      <origin xyz="0 0.05 -0.15"/>
      <material name="color2"/>
    </visual>
    <collision>
      <geometry>
        <box size="0.1 0.1 0.3"/>
      </geometry>
    </collision>
    <inertial>
      <mass value="2.71"/>
      <inertia ixx="1.0" ixy="0.0" ixz="0.0" iyy="1.0" iyz="0.0" izz="1.0"/>
    </inertial>
  </link>
  <link name="left_down_arm">
    <visual>
      <geometry>
        <box size="0.1 0.1 0.3"/>
      </geometry>
      <origin xyz="0 0 -0.15"/>
      <material name="color3"/>
    </visual>
    <collision>
      <geometry>
        <box size="0.1 0.1 0.3"/>
      </geometry>
    </collision>
    <inertial>
      <mass value="2.23"/>
      <inertia ixx="1.0" ixy="0.0" ixz="0.0" iyy="1.0" iyz="0.0" izz="1.0"/>
    </inertial>
  </link>
  <joint name="left_shoulder_to_left_up_arm" type="revolute">
    <parent link="left_shoulder"/>
    <child link="left_up_arm"/>
    <axis xyz="0 1 0"/>
    <limit effort="1000.0" lower="-2.7" upper="0.7" velocity="0.5"/>
    <origin xyz="0 0.0 0"/>
  </joint>
  <transmission name="left_shoulder_to_left_up_arm_trans">
    <type>transmission_interface/SimpleTransmission</type>
    <actuator name="left_shoulder_to_left_up_arm_motor">
      <mechanicalReduction>1</mechanicalReduction>
    </actuator>
    <joint name="left_shoulder_to_left_up_arm">
      <hardwareInterface>hardware_interface/VelocityJointInterface</hardwareInterface>
    </joint>
  </transmission>
  <joint name="left_up_arm_to_left_down_arm" type="revolute">
    <parent link="left_up_arm"/>
    <child link="left_down_arm"/>
    <axis xyz="0 1 0"/>
    <limit effort="1000.0" lower="-2.7" upper="0.5" velocity="0.5"/>
    <origin xyz="0 0.05 -0.3"/>
  </joint>
  <transmission name="left_up_arm_to_left_down_arm_trans">
    <type>transmission_interface/SimpleTransmission</type>
    <actuator name="left_up_arm_to_left_down_arm_motor">
      <mechanicalReduction>1</mechanicalReduction>
    </actuator>
    <joint name="left_up_arm_to_left_down_arm">
      <hardwareInterface>hardware_interface/VelocityJointInterface</hardwareInterface>
    </joint>
  </transmission>
  <link name="right_leg_joint">
    <visual>
      <geometry>
        <box size="0.01 0.01 0.01"/>
      </geometry>
      <origin xyz="0 0.0 0.0"/>
      <material name="color2"/>
    </visual>
    <collision>
      <geometry>
        <box size="0.01 0.01 0.01"/>
      </geometry>
    </collision>
    <inertial>
      <mass value="0.01"/>
      <inertia ixx="1.0" ixy="0.0" ixz="0.0" iyy="1.0" iyz="0.0" izz="1.0"/>
    </inertial>
  </link>
  <link name="right_up_leg">
    <visual>
      <geometry>
        <box size="0.18 0.18 0.3"/>
      </geometry>
      <origin xyz="0 0 -0.15"/>
      <material name="color2"/>
    </visual>
    <collision>
      <geometry>
        <box size="0.18 0.18 0.3"/>
      </geometry>
    </collision>
    <inertial>
      <mass value="14.16"/>
      <inertia ixx="1.0" ixy="0.0" ixz="0.0" iyy="1.0" iyz="0.0" izz="1.0"/>
    </inertial>
  </link>
  <link name="right_down_leg">
    <visual>
      <geometry>
        <box size="0.18 0.18 0.3"/>
      </geometry>
      <origin xyz="0 0 -0.15"/>
      <material name="color3"/>
    </visual>
    <collision>
      <geometry>
        <box size="0.18 0.18 0.3"/>
      </geometry>
    </collision>
    <inertial>
      <mass value="4.33"/>
      <inertia ixx="1.0" ixy="0.0" ixz="0.0" iyy="1.0" iyz="0.0" izz="1.0"/>
    </inertial>
  </link>
  <link name="right_foot">
    <visual>
      <geometry>
        <box size="0.24 0.18 0.04"/>
      </geometry>
      <origin xyz="0.02 0 -0.02"/>
      <material name="color4"/>
    </visual>
    <collision>
      <geometry>
        <box size="0.24 0.18 0.04"/>
      </geometry>
    </collision>
    <inertial>
      <mass value="1.37"/>
      <inertia ixx="1.0" ixy="0.0" ixz="0.0" iyy="1.0" iyz="0.0" izz="1.0"/>
    </inertial>
  </link>
  <joint name="body_to_right_leg_joint" type="revolute">
    <parent link="base_link"/>
    <child link="right_leg_joint"/>
    <axis xyz="1 0 0"/>
    <limit effort="1000.0" lower="-2.7" upper="-0.0" velocity="0.5"/>
    <origin xyz="0 -0.1 -0.3"/>
  </joint>
  <transmission name="body_to_right_leg_joint_trans">
    <type>transmission_interface/SimpleTransmission</type>
    <actuator name="body_to_right_leg_joint_motor">
      <mechanicalReduction>1</mechanicalReduction>
    </actuator>
    <joint name="body_to_right_leg_joint">
      <hardwareInterface>hardware_interface/VelocityJointInterface</hardwareInterface>
    </joint>
  </transmission>
  <joint name="right_leg_joint_to_right_up_leg" type="revolute">
    <parent link="right_leg_joint"/>
    <child link="right_up_leg"/>
    <origin xyz="0 0.0 0"/>
    <axis xyz="0 1 0"/>
    <limit effort="1000.0" lower="-2" upper="1.0" velocity="0.5"/>
  </joint>
  <transmission name="right_leg_joint_to_right_up_leg_trans">
    <type>transmission_interface/SimpleTransmission</type>
    <actuator name="right_leg_joint_to_right_up_leg_motor">
      <mechanicalReduction>1</mechanicalReduction>
    </actuator>
    <joint name="right_leg_joint_to_right_up_leg">
      <hardwareInterface>hardware_interface/VelocityJointInterface</hardwareInterface>
    </joint>
  </transmission>
  <joint name="right_up_leg_to_right_down_leg" type="revolute">
    <parent link="right_up_leg"/>
    <child link="right_down_leg"/>
    <axis xyz="0 1 0"/>
    <limit effort="1000.0" lower="-0.1" upper="2.0" velocity="0.5"/>
    <origin xyz="0 0 -0.3"/>
  </joint>
  <transmission name="right_up_leg_to_right_down_leg_trans">
    <type>transmission_interface/SimpleTransmission</type>
    <actuator name="right_up_leg_to_right_down_leg_motor">
      <mechanicalReduction>1</mechanicalReduction>
    </actuator>
    <joint name="right_up_leg_to_right_down_leg">
      <hardwareInterface>hardware_interface/VelocityJointInterface</hardwareInterface>
    </joint>
  </transmission>
  <joint name="right_down_leg_to_right_foot" type="revolute">
    <parent link="right_down_leg"/>
    <child link="right_foot"/>
    <axis xyz="0 1 0"/>
    <limit effort="1000.0" lower="-0.5" upper="1.0" velocity="0.5"/>
    <origin xyz="0 0 -0.3"/>
  </joint>
  <transmission name="right_down_leg_to_right_foot">
    <type>transmission_interface/SimpleTransmission</type>
    <actuator name="right_down_leg_to_right_foot">
      <mechanicalReduction>1</mechanicalReduction>
    </actuator>
    <joint name="right_down_leg_to_right_foot">
      <hardwareInterface>hardware_interface/VelocityJointInterface</hardwareInterface>
    </joint>
  </transmission>
  <link name="left_leg_joint">
    <visual>
      <geometry>
        <box size="0.01 0.01 0.01"/>
      </geometry>
      <origin xyz="0 0.0 0.0"/>
      <material name="color2"/>
    </visual>
    <collision>
      <geometry>
        <box size="0.01 0.01 0.01"/>
      </geometry>
    </collision>
    <inertial>
      <mass value="0.01"/>
      <inertia ixx="1.0" ixy="0.0" ixz="0.0" iyy="1.0" iyz="0.0" izz="1.0"/>
    </inertial>
  </link>
  <link name="left_up_leg">
    <visual>
      <geometry>
        <box size="0.18 0.18 0.3"/>
      </geometry>
      <origin xyz="0 0 -0.15"/>
      <material name="color2"/>
    </visual>
    <collision>
      <geometry>
        <box size="0.18 0.18 0.3"/>
      </geometry>
    </collision>
    <inertial>
      <mass value="14.16"/>
      <inertia ixx="1.0" ixy="0.0" ixz="0.0" iyy="1.0" iyz="0.0" izz="1.0"/>
    </inertial>
  </link>
  <link name="left_down_leg">
    <visual>
      <geometry>
        <box size="0.18 0.18 0.3"/>
      </geometry>
      <origin xyz="0 0 -0.15"/>
      <material name="color3"/>
    </visual>
    <collision>
      <geometry>
        <box size="0.18 0.18 0.3"/>
      </geometry>
    </collision>
    <inertial>
      <mass value="4.33"/>
      <inertia ixx="1.0" ixy="0.0" ixz="0.0" iyy="1.0" iyz="0.0" izz="1.0"/>
    </inertial>
  </link>
  <link name="left_foot">
    <visual>
      <geometry>
        <box size="0.24 0.18 0.04"/>
      </geometry>
      <origin xyz="0.02 0 -0.02"/>
      <material name="color4"/>
    </visual>
    <collision>
      <geometry>
        <box size="0.24 0.18 0.04"/>
      </geometry>
    </collision>
    <inertial>
      <mass value="1.37"/>
      <inertia ixx="1.0" ixy="0.0" ixz="0.0" iyy="1.0" iyz="0.0" izz="1.0"/>
    </inertial>
  </link>
  <joint name="body_to_left_leg_joint" type="revolute">
    <parent link="base_link"/>
    <child link="left_leg_joint"/>
    <axis xyz="1 0 0"/>
    <limit effort="1000.0" lower="-0.0" upper="2.7" velocity="0.5"/>
    <origin xyz="0 0.1 -0.3"/>
  </joint>
  <transmission name="body_to_left_leg_joint_trans">
    <type>transmission_interface/SimpleTransmission</type>
    <actuator name="body_to_left_leg_joint_motor">
      <mechanicalReduction>1</mechanicalReduction>
    </actuator>
    <joint name="body_to_left_leg_joint">
      <hardwareInterface>hardware_interface/VelocityJointInterface</hardwareInterface>
    </joint>
  </transmission>
  <joint name="left_leg_joint_to_left_up_leg" type="revolute">
    <parent link="left_leg_joint"/>
    <child link="left_up_leg"/>
    <origin xyz="0 0.0 0"/>
    <axis xyz="0 1 0"/>
    <limit effort="1000.0" lower="-2" upper="1.0" velocity="0.5"/>
  </joint>
  <transmission name="left_leg_joint_to_left_up_leg_trans">
    <type>transmission_interface/SimpleTransmission</type>
    <actuator name="left_leg_joint_to_left_up_leg_motor">
      <mechanicalReduction>1</mechanicalReduction>
    </actuator>
    <joint name="left_leg_joint_to_left_up_leg">
      <hardwareInterface>hardware_interface/VelocityJointInterface</hardwareInterface>
    </joint>
  </transmission>
  <joint name="left_up_leg_to_left_down_leg" type="revolute">
    <parent link="left_up_leg"/>
    <child link="left_down_leg"/>
    <axis xyz="0 1 0"/>
    <limit effort="1000.0" lower="-0.1" upper="2.0" velocity="0.5"/>
    <origin xyz="0 0 -0.3"/>
  </joint>
  <transmission name="left_up_leg_to_left_down_leg_trans">
    <type>transmission_interface/SimpleTransmission</type>
    <actuator name="left_up_leg_to_left_down_leg_motor">
      <mechanicalReduction>1</mechanicalReduction>
    </actuator>
    <joint name="left_up_leg_to_left_down_leg">
      <hardwareInterface>hardware_interface/VelocityJointInterface</hardwareInterface>
    </joint>
  </transmission>
  <joint name="left_down_leg_to_left_foot" type="revolute">
    <parent link="left_down_leg"/>
    <child link="left_foot"/>
    <axis xyz="0 1 0"/>
    <limit effort="1000.0" lower="-0.5" upper="1.0" velocity="0.5"/>
    <origin xyz="0 0 -0.3"/>
  </joint>
  <transmission name="left_down_leg_to_left_foot">
    <type>transmission_interface/SimpleTransmission</type>
    <actuator name="left_down_leg_to_left_foot">
      <mechanicalReduction>1</mechanicalReduction>
    </actuator>
    <joint name="left_down_leg_to_left_foot">
      <hardwareInterface>hardware_interface/VelocityJointInterface</hardwareInterface>
    </joint>
  </transmission>
  <gazebo>
    <plugin filename="libgazebo_ros_control.so" name="gazebo_ros_control">
      <robotNamespace>/</robotNamespace>
    </plugin>
  </gazebo>
</robot>

